<?xml version="1.0"?>
<robot name="ur12">

  <!--
    SCOPE: this is a deliberately minimal URDF — six revolute joints, the
    fixed flange, and a <ros2_control> block pointing at our hardware
    interface plugin. It satisfies controller_manager's validation step
    so JointStateBroadcaster can spawn. Nothing else.

    DELIBERATELY MISSING (not bugs — out of scope for this PoC):
      - <origin xyz="..." rpy="..."> on every joint. Without these every
        link sits at the world origin: TF lies, FK/IK lie, RViz misleads.
        The current driver doesn't consume TF so this is invisible today,
        but it is the FIRST thing to fix when wiring MoveIt2 or RViz.
      - <inertial> mass / center / tensor. Required for effort or
        computed-torque controllers, gravity compensation, and mass-aware
        motion planning. Not required for pure position control.
      - <visual> meshes. Cosmetic for RViz / Gazebo only.
      - <collision> primitives. Required for self- and environment-collision
        checking in MoveIt2.
      - Real UR12 joint limits. The placeholders below are loose ±2π values;
        actual UR12 limits are tighter on shoulder_lift in particular.

    PRODUCTION PATH: replace this file with `Universal_Robots_ROS2_Description`
    (apt: ros-jazzy-ur-description), processed via xacro at launch time.
    Strip the upstream <ros2_control> block and inject the one below in its
    place — the upstream URDF assumes ur_robot_driver's hardware plugin, not
    ours. Drop the visual meshes if image size matters; everything else is
    load-bearing for production.
  -->

  <link name="base_link"/>
  <link name="shoulder_link"/>
  <link name="upper_arm_link"/>
  <link name="forearm_link"/>
  <link name="wrist_1_link"/>
  <link name="wrist_2_link"/>
  <link name="wrist_3_link"/>
  <link name="tool0"/>

  <joint name="shoulder_pan_joint" type="revolute">
    <parent link="base_link"/>
    <child link="shoulder_link"/>
    <axis xyz="0 0 1"/>
    <limit lower="-6.28" upper="6.28" effort="150" velocity="3.14"/>
  </joint>

  <joint name="shoulder_lift_joint" type="revolute">
    <parent link="shoulder_link"/>
    <child link="upper_arm_link"/>
    <axis xyz="0 1 0"/>
    <limit lower="-6.28" upper="6.28" effort="150" velocity="3.14"/>
  </joint>

  <joint name="elbow_joint" type="revolute">
    <parent link="upper_arm_link"/>
    <child link="forearm_link"/>
    <axis xyz="0 1 0"/>
    <limit lower="-3.14" upper="3.14" effort="150" velocity="3.14"/>
  </joint>

  <joint name="wrist_1_joint" type="revolute">
    <parent link="forearm_link"/>
    <child link="wrist_1_link"/>
    <axis xyz="0 1 0"/>
    <limit lower="-6.28" upper="6.28" effort="54" velocity="6.28"/>
  </joint>

  <joint name="wrist_2_joint" type="revolute">
    <parent link="wrist_1_link"/>
    <child link="wrist_2_link"/>
    <axis xyz="0 0 1"/>
    <limit lower="-6.28" upper="6.28" effort="54" velocity="6.28"/>
  </joint>

  <joint name="wrist_3_joint" type="revolute">
    <parent link="wrist_2_link"/>
    <child link="wrist_3_link"/>
    <axis xyz="0 1 0"/>
    <limit lower="-6.28" upper="6.28" effort="54" velocity="6.28"/>
  </joint>

  <joint name="wrist_3_flange" type="fixed">
    <parent link="wrist_3_link"/>
    <child link="tool0"/>
  </joint>

  <!-- ros2_control hardware interface -->
  <ros2_control name="Ur12HardwareInterface" type="system">
    <hardware>
      <plugin>ur12_driver/Ur12HardwareInterface</plugin>
      <param name="robot_host">ursim</param>
      <param name="publish_rate">125.0</param>
    </hardware>
    <joint name="shoulder_pan_joint">
      <command_interface name="position"/>
      <state_interface name="position"/>
      <state_interface name="velocity"/>
    </joint>
    <joint name="shoulder_lift_joint">
      <command_interface name="position"/>
      <state_interface name="position"/>
      <state_interface name="velocity"/>
    </joint>
    <joint name="elbow_joint">
      <command_interface name="position"/>
      <state_interface name="position"/>
      <state_interface name="velocity"/>
    </joint>
    <joint name="wrist_1_joint">
      <command_interface name="position"/>
      <state_interface name="position"/>
      <state_interface name="velocity"/>
    </joint>
    <joint name="wrist_2_joint">
      <command_interface name="position"/>
      <state_interface name="position"/>
      <state_interface name="velocity"/>
    </joint>
    <joint name="wrist_3_joint">
      <command_interface name="position"/>
      <state_interface name="position"/>
      <state_interface name="velocity"/>
    </joint>
  </ros2_control>

</robot>
